Workbook
Name _msoanchor_1: 表紙!$I$7
Name _msoanchor_2: 表紙!#REF!
Name _msocom_1: 表紙!$A$36

Sheet 表紙
A6: 御 見 積 書
D7: 御中 | I7: =TODAY() -> 46312
B10: 下記の通り御見積致しますので宜しくお願い申し上げます。
B12: 合 計 | C12: =I33 -> 0 | H12: 東京都知事許可（般2）第12226号
H13: 消防庁認定第12703号
H14: 東京カーペット加工 株式会社
B15: 工 事 名 | H15: 〒130-0012
H16: 東京都墨田区太平4-6-6
B17: 工事概要 | H17: ＴＥＬ03-3625-4169 ＦＡＸ03-3626-2669
B18: 見積有効期限 | C18: 1ヶ月間
B19: 取 引 条 件 | C19: 別途ご相談の上決定
B21: 品 名 | D21: 仕様・規格・寸法 | F21: 数量 | G21: 単位 | H21: 単価 | I21: 金額 | K21: 備考
I22: =F22*H22 -> 0
I23: =F23*H23 -> 0
I24: =F24*H24 -> 0
I25: =F25*H25 -> 0
I26: =F26*H26 -> 0
I27: =F27*H27 -> 0
I28: =F28*H28 -> 0
I29: =F29*H29 -> 0
I30: =F30*H30 -> 0
I31: =F31*H31 -> 0
I32: =F32*H32 -> 0
A33: 備 考 | F33: 合計 | I33: =SUM(I22:J32) -> 0
H35: ※上記価格には消費税は含まれておりません。

Sheet 内訳書
A1: 工 事 名 | C1: =表紙!C15 -> 0 | F1: 内 訳 明 細 書 | J1: 東京カーペット加工㈱ １
B2: 品 名 | D2: 仕様・規格・寸法 | F2: 数量 | G2: 単位 | H2: 単価 | I2: 金額 | K2: 備考
I3: =SUM(F3*H3) -> 0
I4: =SUM(F4*H4) -> 0
I5: =SUM(F5*H5) -> 0
I6: =SUM(F6*H6) -> 0
I7: =SUM(F7*H7) -> 0
I8: =SUM(F8*H8) -> 0
I9: =SUM(F9*H9) -> 0
I10: =SUM(F10*H10) -> 0
I11: =SUM(F11*H11) -> 0
I12: =SUM(F12*H12) -> 0
I13: =SUM(F13*H13) -> 0
I14: =SUM(F14*H14) -> 0
... I24: =SUM(F24*H24) -> 0
C25: 計 | I25: =SUM(I2:J24) -> 0
A26: 工 事 名 | C26: =表紙!C40 -> 0 | F26: 内 訳 明 細 書 | J26: 東京カーペット加工㈱ 2
B27: 品 名 | D27: 仕様・規格・寸法 | F27: 数量 | G27: 単位 | H27: 単価 | I27: 金額 | K27: 備考
I28: =SUM(F28*H28) -> 0
I29: =SUM(F29*H29) -> 0
I30: =SUM(F30*H30) -> 0
I31: =SUM(F31*H31) -> 0
I32: =SUM(F32*H32) -> 0
I33: =SUM(F33*H33) -> 0
I34: =SUM(F34*H34) -> 0
I35: =SUM(F35*H35) -> 0
I36: =SUM(F36*H36) -> 0
I37: =SUM(F37*H37) -> 0
I38: =SUM(F38*H38) -> 0
I39: =SUM(F39*H39) -> 0
... I49: =SUM(F49*H49) -> 0
C50: 計 | I50: =SUM(I27:J49) -> 0
A51: 工 事 名 | C51: =表紙!C65 -> 0 | F51: 内 訳 明 細 書 | J51: 東京カーペット加工㈱ 3
B52: 品 名 | D52: 仕様・規格・寸法 | F52: 数量 | G52: 単位 | H52: 単価 | I52: 金額 | K52: 備考
I53: =SUM(F53*H53) -> 0
I54: =SUM(F54*H54) -> 0
I55: =SUM(F55*H55) -> 0
I56: =SUM(F56*H56) -> 0
I57: =SUM(F57*H57) -> 0
I58: =SUM(F58*H58) -> 0
...

Sheet マスタ
B3: 単位 | C3: 仕様1 | D3: 仕様2 | E3: 仕様3
B4: ㎡ | C4: エントランス | D4: 天井 | E4: サンゲツ
B5: ｍ | C5: 通路 | D5: 壁 | E5: リリカラ
B6: ヶ所 | C6: 接客スペース | D6: 天井・壁 | E6: 東リ
B7: 式 | C7: 接客個室 | D7: 巾木 | E7: シンコール
B8: 枚 | C8: 模型室 | D8: 床 | E8: ルノン
B9: 箱 | C9: 模型・展示スペース | D9: 折り上げ天井 | E9: トキワ
B10: 本 | C10: 展示スペース | D10: 折り下げ天井 | E10: トミタ
B11: 組 | C11: 事務所・倉庫 | D11: アクセント天井 | E11: テシード
B12: 台 | C12: 事務所 | D12: アクセント壁 | E12: マナトレーディング
B13: 段 | C13: 倉庫 | D13: アクセント柱 | E13: 旭興
B14: 窓 | C14: トイレ | D14: 柱
B15: ヶ | C15: 男子トイレ
B16: ケース | C16: 女子トイレ
B17: セット
B18: 人工
